Workbook

Sheet STAI y SNAP
A1: STAI | F1: Resultado SNAP
A2: # | B2: Respuesta | F2: Suma de puntajes | G2: Puntaje final
A3: 1 | B3: 1 | F3: 1 | G3: =F3/9 -> 0.11111111
A4: 2 | B4: 1 | F4: 2 | G4: =F4/9 -> 0.22222222
A5: 3 | B5: 3 | F5: 3 | G5: =F5/9 -> 0.33333333
A6: 4 | B6: 1 | F6: 4 | G6: =F6/9 -> 0.44444444
A7: 5 | B7: 2 | F7: 5 | G7: =F7/9 -> 0.55555556
A8: 6 | B8: 1 | F8: 6 | G8: =F8/9 -> 0.66666667
A9: 7 | B9: 0 | F9: 7 | G9: =F9/9 -> 0.77777778
A10: 8 | B10: 3 | F10: 8 | G10: =F10/9 -> 0.88888889
A11: 9 | B11: 1 | F11: 9 | G11: =F11/9 -> 1
A12: 10 | B12: 0 | F12: 10 | G12: =F12/9 -> 1.1111111
A13: 11 | B13: 2 | F13: 11 | G13: =F13/9 -> 1.2222222
A14: 12 | B14: 3 | F14: 12 | G14: =F14/9 -> 1.3333333
... A16: 14 | B16: 3 | F16: 14 | G16: =F16/9 -> 1.5555556
A17: 15 | B17: 3 | C17: Estado | F17: 15 | G17: =F17/9 -> 1.6666667
A18: 16 | B18: 1 | C18: A | D18: =B5+B6+B8+B9+B11+B14+B15+B16+B19+B20 -> 17 | F18: 16 | G18: =F18/9 -> 1.7777778
A19: 17 | B19: 3 | C19: B | D19: =B3+B4+B7+B10+B12+B13+B17+B18+B21+B22 -> 16 | F19: 17 | G19: =F19/9 -> 1.8888889
A20: 18 | B20: 1 | C20: Total Estado | D20: =(D18-D19)+50 -> 51 | F20: 18 | G20: =F20/9 -> 2
A21: 19 | B21: 2 | F21: 19 | G21: =F21/9 -> 2.1111111
A22: 20 | B22: 1 | C22: Rasgo | F22: 20 | G22: =F22/9 -> 2.2222222
A23: 21 | B23: 2 | C23: 2 | D23: 1 | F23: 21 | G23: =F23/9 -> 2.3333333
A24: 22 | B24: 3 | C24: B | D24: =B23+B29+B30+B33+B37+B39 -> 7 | F24: 22 | G24: =F24/9 -> 2.4444444
A25: 23 | B25: 1 | C25: Total Rasgo | D25: =(D23-D24)+35 -> 29 | F25: 23 | G25: =F25/9 -> 2.5555556
A26: 24 | B26: 2 | F26: 24 | G26: =F26/9 -> 2.6666667
A27: 25 | B27: 0 | F27: 25 | G27: =F27/9 -> 2.7777778
A28: 26 | B28: 2 | F28: 26 | G28: =F28/9 -> 2.8888889
A29: 27 | B29: 1 | F29: 27 | G29: =F29/9 -> 3
A30: 28 | B30: 1
A31: 29 | B31: 3
A32: 30 | B32: 1
A33: 31 | B33: 1
A34: 32 | B34: 1
A35: 33 | B35: 2
A36: 34 | B36: 3
A37: 35 | B37: 1
A38: 36 | B38: 2
A39: 37 | B39: 1
A40: 38 | B40: 1
A41: 39 | B41: 1
...

Sheet STAI
A1: STAI
C2: A | D2: B | E2: Total
A3: Estado | B3: 30+A-B | C3: =SUM(D8:D9,D12,D15,D17,D18,D22,D23,D26,D27) -> 22 | D3: =SUM(D10:D11,D13,D14,D16,D19,D20,D21,D24,D25) -> 9 | E3: =(30+C3)-D3 -> 43 | F3: Estado
A4: Rasgo | B4: 21+A-B | C4: =SUM(G8,G13,G14,G17,G20,G23,G26) -> 15 | D4: =SUM(G9:G12,G15,G16,G18,G19,G21,G22,G24,G25,G27) -> 14 | E4: =(30+C4)-D4 -> 31 | F4: Rasgo
B7: Estado ítem | C7: PD | D7: PB | E7: Rasgo ítem | F7: PD | G7: PB
B8: 1 | C8: 1 | D8: =IF(C8=0,3,IF(C8=1,2,IF(C8=2,1,IF(B8>=3,0,"Fuera de Rango")))) -> 2 | E8: 21 | F8: 1 | G8: =IF(F8=0,3,IF(F8=1,2,IF(F8=2,1,IF(E8>=3,0,"Fuera de Rango")))) -> 2
B9: 2 | C9: 1 | D9: =IF(C9=0,3,IF(C9=1,2,IF(C9=2,1,IF(B9>=3,0,"Fuera de Rango")))) -> 2 | E9: 22 | F9: 1 | G9: =F9 -> 1
B10: 3 | C10: 2 | D10: =C10 -> 2 | E10: 23 | F10: 0 | G10: =F10 -> 0
B11: 4 | C11: 0 | D11: =C11 -> 0 | E11: 24 | F11: 2 | G11: =F11 -> 2
B12: 5 | C12: 1 | D12: =IF(C12=0,3,IF(C12=1,2,IF(C12=2,1,IF(B12>=3,0,"Fuera de Rango")))) -> 2 | E12: 25 | F12: 1 | G12: =F12 -> 1
B13: 6 | C13: 1 | D13: =C13 -> 1 | E13: 26 | F13: 1 | G13: =IF(F13=0,3,IF(F13=1,2,IF(F13=2,1,IF(E13>=3,0,"Fuera de Rango")))) -> 2
B14: 7 | C14: 1 | D14: =C14 -> 1 | E14: 27 | F14: 0 | G14: =IF(F14=0,3,IF(F14=1,2,IF(F14=2,1,IF(E14>=3,0,"Fuera de Rango")))) -> 3
B15: 8 | C15: 0 | D15: =IF(C15=0,3,IF(C15=1,2,IF(C15=2,1,IF(B15>=3,0,"Fuera de Rango")))) -> 3 | E15: 28 | F15: 0 | G15: =F15 -> 0
B16: 9 | C16: 1 | D16: =C16 -> 1 | E16: 29 | F16: 2 | G16: =F16 -> 2
B17: 10 | C17: 0 | D17: =IF(C17=0,3,IF(C17=1,2,IF(C17=2,1,IF(B17>=3,0,"Fuera de Rango")))) -> 3 | E17: 30 | F17: 1 | G17: =IF(F17=0,3,IF(F17=1,2,IF(F17=2,1,IF(E17>=3,0,"Fuera de Rango")))) -> 2
B18: 11 | C18: 2 | D18: =IF(C18=0,3,IF(C18=1,2,IF(C18=2,1,IF(B18>=3,0,"Fuera de Rango")))) -> 1 | E18: 31 | F18: 2 | G18: =F18 -> 2
B19: 12 | C19: 0 | D19: =C19 -> 0 | E19: 32 | F19: 0 | G19: =F19 -> 0
B20: 13 | C20: 1 | D20: =C20 -> 1 | E20: 33 | F20: 1 | G20: =IF(F20=0,3,IF(F20=1,2,IF(F20=2,1,IF(E20>=3,0,"Fuera de Rango")))) -> 2
B21: 14 | C21: 1 | D21: =C21 -> 1 | E21: 34 | F21: 0 | G21: =F21 -> 0
B22: 15 | C22: 0 | D22: =IF(C22=0,3,IF(C22=1,2,IF(C22=2,1,IF(B22>=3,0,"Fuera de Rango")))) -> 3 | E22: 35 | F22: 2 | G22: =F22 -> 2
B23: 16 | C23: 1 | D23: =IF(C23=0,3,IF(C23=1,2,IF(C23=2,1,IF(B23>=3,0,"Fuera de Rango")))) -> 2 | E23: 36 | F23: 1 | G23: =IF(F23=0,3,IF(F23=1,2,IF(F23=2,1,IF(E23>=3,0,"Fuera de Rango")))) -> 2
B24: 17 | C24: 1 | D24: =C24 -> 1 | E24: 37 | F24: 1 | G24: =F24 -> 1
B25: 18 | C25: 1 | D25: =C25 -> 1 | E25: 38 | F25: 1 | G25: =F25 -> 1
B26: 19 | C26: 1 | D26: =IF(C26=0,3,IF(C26=1,2,IF(C26=2,1,IF(B26>=3,0,"Fuera de Rango")))) -> 2 | E26: 39 | F26: 1 | G26: =IF(F26=0,3,IF(F26=1,2,IF(F26=2,1,IF(E26>=3,0,"Fuera de Rango")))) -> 2
B27: 20 | C27: 1 | D27: =IF(C27=0,3,IF(C27=1,2,IF(C27=2,1,IF(B27>=3,0,"Fuera de Rango")))) -> 2 | E27: 40 | F27: 2 | G27: =F27 -> 2
C28: Estado | D28: =E3 -> 43 | F28: Rasgo | G28: =E4 -> 31

Sheet STAI Original
B2: Estado
B3: Puntaje invertido
B4: A: | C4: 1 | D4: 2 | E4: 5 | F4: 8 | G4: 10 | H4: 11 | I4: 15 | J4: 16 | K4: 19 | L4: 20
B5: Puntaje | C5: 2 | D5: 2 | E5: 2 | F5: 2 | G5: 1 | H5: 1 | I5: 1 | J5: 1 | K5: 1 | L5: 2
B6: Corregido | C6: =IF(C5=0,3,IF(C5=1,2,IF(C5=2,1,IF(C5>=3,0,"Fuera de Rango")))) -> 1 | D6: =IF(D5=0,3,IF(D5=1,2,IF(D5=2,1,IF(D5>=3,0,"Fuera de Rango")))) -> 1 | E6: =IF(E5=0,3,IF(E5=1,2,IF(E5=2,1,IF(E5>=3,0,"Fuera de Rango")))) -> 1 | F6: =IF(F5=0,3,IF(F5=1,2,IF(F5=2,1,IF(F5>=3,0,"Fuera de Rango")))) -> 1 | G6: =IF(G5=0,3,IF(G5=1,2,IF(G5=2,1,IF(G5>=3,0,"Fuera de Rango")))) -> 2 | H6: =IF(H5=0,3,IF(H5=1,2,IF(H5=2,1,IF(H5>=3,0,"Fuera de Rango")))) -> 2 | I6: =IF(I5=0,3,IF(I5=1,2,IF(I5=2,1,IF(I5>=3,0,"Fuera de Rango")))) -> 2 | J6: =IF(J5=0,3,IF(J5=1,2,IF(J5=2,1,IF(J5>=3,0,"Fuera de Rango")))) -> 2 | ... L6: =IF(L5=0,3,IF(L5=1,2,IF(L5=2,1,IF(L5>=3,0,"Fuera de Rango")))) -> 1
B8: Puntaje directo
B9: B ítem: | C9: 3 | D9: 4 | E9: 6 | F9: 7 | G9: 9 | H9: 12 | I9: 13 | J9: 14 | K9: 17 | L9: 18
B10: Puntaje | C10: 1 | D10: 1 | E10: 0 | F10: 1 | G10: 0 | H10: 1 | I10: 0 | J10: 0 | K10: 0 | L10: 0
B12: Rasgo
B13: Puntaje invertido
B14: A: | C14: 21 | D14: 26 | E14: 27 | F14: 30 | G14: 33 | H14: 36 | I14: 39
B15: Puntaje | C15: 2 | D15: 3 | E15: 3 | F15: 2 | G15: 2 | H15: 0 | I15: 2
B16: Corregido | C16: =STAI!C8=IF(C15=0,3,IF(C15=1,2,IF(C15=2,1,IF(C15>=3,0,"Fuera de Rango")))) -> TRUE | D16: =IF(D15=0,3,IF(D15=1,2,IF(D15=2,1,IF(D15>=3,0,"Fuera de Rango")))) -> 0 | E16: =IF(E15=0,3,IF(E15=1,2,IF(E15=2,1,IF(E15>=3,0,"Fuera de Rango")))) -> 0 | F16: =IF(F15=0,3,IF(F15=1,2,IF(F15=2,1,IF(F15>=3,0,"Fuera de Rango")))) -> 1 | G16: =IF(G15=0,3,IF(G15=1,2,IF(G15=2,1,IF(G15>=3,0,"Fuera de Rango")))) -> 1 | H16: =IF(H15=0,3,IF(H15=1,2,IF(H15=2,1,IF(H15>=3,0,"Fuera de Rango")))) -> 3 | I16: =IF(I15=0,3,IF(I15=1,2,IF(I15=2,1,IF(I15>=3,0,"Fuera de Rango")))) -> 1
B18: Puntaje directo
B19: B ítem: | C19: 22 | D19: 23 | E19: 24 | F19: 25 | G19: 28 | H19: 29 | I19: 31 | J19: 32 | K19: 34 | L19: 35 | M19: 37 | N19: 38 | O19: 40
B20: Puntaje | C20: 1 | D20: 0 | E20: 0 | F20: 0 | G20: 0 | H20: 1 | I20: 1 | J20: 0 | K20: 1 | L20: 1 | M20: 1 | N20: 0 | O20: 1
D25: A | E25: B | F25: Total
B26: Estado | C26: 30+A-B | D26: =SUM('STAI Original'!D9:M9) -> 100 | E26: =SUM('STAI Original'!D13:M13) -> 0 | F26: =(30+D26)-E26 -> 130 | G26: Estado
B27: Rasgo | C27: 21+A-B | D27: =SUM('STAI Original'!D19:J19) -> 192 | E27: =SUM('STAI Original'!D23:P23) -> 0 | F27: =(30+D27)-E27 -> 222 | G27: Rasgo
F37: A | G37: B | H37: Total
D38: Estado | E38: 30+A-B | F38: =SUM(G43:G44,G47,G50,G52,G53,G57,G58,G61,G62) -> 15 | G38: =SUM(G45:G46,G48,G49,G51,G54,G55,G56,G59,G60) -> 20 | H38: =(30+F38)-G38 -> 25 | I38: Estado
D39: Rasgo | E39: 21+A-B | F39: =SUM(J43,J48,J49,J52,J55,J58,J61) -> 14 | G39: =SUM(J44:J47,J50,J51,J53,J54,J56,J57,J59,J60,J62) -> 13 | H39: =(30+F39)-G39 -> 31 | I39: Rasgo
E42: Estado ítem | F42: PD | G42: PB | H42: Rasgo ítem | I42: PD | J42: PB
E43: 1 | F43: 1 | G43: =IF(F43=0,3,IF(F43=1,2,IF(F43=2,1,IF(E43>=3,0,"Fuera de Rango")))) -> 2 | H43: 21 | I43: 1 | J43: =IF(I43=0,3,IF(I43=1,2,IF(I43=2,1,IF(H43>=3,0,"Fuera de Rango")))) -> 2
E44: 2 | F44: 2 | G44: =IF(F44=0,3,IF(F44=1,2,IF(F44=2,1,IF(E44>=3,0,"Fuera de Rango")))) -> 1 | H44: 22 | I44: 1 | J44: =I44 -> 1
E45: 3 | F45: 2 | G45: =F45 -> 2 | H45: 23 | I45: 1 | J45: =I45 -> 1
E46: 4 | F46: 3 | G46: =F46 -> 3 | H46: 24 | I46: 1 | J46: =I46 -> 1
E47: 5 | F47: 1 | G47: =IF(F47=0,3,IF(F47=1,2,IF(F47=2,1,IF(E47>=3,0,"Fuera de Rango")))) -> 2 | H47: 25 | I47: 1 | J47: =I47 -> 1
E48: 6 | F48: 2 | G48: =F48 -> 2 | H48: 26 | I48: 1 | J48: =IF(I48=0,3,IF(I48=1,2,IF(I48=2,1,IF(H48>=3,0,"Fuera de Rango")))) -> 2
E49: 7 | F49: 3 | G49: =F49 -> 3 | H49: 27 | I49: 1 | J49: =IF(I49=0,3,IF(I49=1,2,IF(I49=2,1,IF(H49>=3,0,"Fuera de Rango")))) -> 2
E50: 8 | F50: 2 | G50: =IF(F50=0,3,IF(F50=1,2,IF(F50=2,1,IF(E50>=3,0,"Fuera de Rango")))) -> 1 | H50: 28 | I50: 1 | J50: =I50 -> 1
E51: 9 | F51: 1 | G51: =F51 -> 1 | H51: 29 | I51: 1 | J51: =I51 -> 1
E52: 10 | F52: 1 | G52: =IF(F52=0,3,IF(F52=1,2,IF(F52=2,1,IF(E52>=3,0,"Fuera de Rango")))) -> 2 | H52: 30 | I52: 1 | J52: =IF(I52=0,3,IF(I52=1,2,IF(I52=2,1,IF(H52>=3,0,"Fuera de Rango")))) -> 2
E53: 11 | F53: 1 | G53: =IF(F53=0,3,IF(F53=1,2,IF(F53=2,1,IF(E53>=3,0,"Fuera de Rango")))) -> 2 | H53: 31 | I53: 1 | J53: =I53 -> 1
E54: 12 | F54: 2 | G54: =F54 -> 2 | H54: 32 | I54: 1 | J54: =I54 -> 1
E55: 13 | F55: 2 | G55: =F55 -> 2 | H55: 33 | I55: 1 | J55: =IF(I55=0,3,IF(I55=1,2,IF(I55=2,1,IF(H55>=3,0,"Fuera de Rango")))) -> 2
E56: 14 | F56: 2 | G56: =F56 -> 2 | H56: 34 | I56: 1 | J56: =I56 -> 1
E57: 15 | F57: 2 | G57: =IF(F57=0,3,IF(F57=1,2,IF(F57=2,1,IF(E57>=3,0,"Fuera de Rango")))) -> 1 | H57: 35 | I57: 1 | J57: =I57 -> 1
E58: 16 | F58: 2 | G58: =IF(F58=0,3,IF(F58=1,2,IF(F58=2,1,IF(E58>=3,0,"Fuera de Rango")))) -> 1 | H58: 36 | I58: 1 | J58: =IF(I58=0,3,IF(I58=1,2,IF(I58=2,1,IF(H58>=3,0,"Fuera de Rango")))) -> 2
E59: 17 | F59: 1 | G59: =F59 -> 1 | H59: 37 | I59: 1 | J59: =I59 -> 1
...

Sheet Toulouse- Pieron IGAP
A1: I
C3: Aciertos | D3: 200
C4: Errores | D4: 10
C5: Omisiones | D5: 5
C7: IGAP PD: | D7: =D3-(D4+D5) -> 185

Sheet SNAP
B2: Resultado SNAP
B3: Suma de puntajes | C3: Puntaje final | D3: Meter a la base
B4: 1 | C4: =B4/9 -> 0.11111111 | D4: 1
B5: 2 | C5: =B5/9 -> 0.22222222 | D5: 2
B6: 3 | C6: =B6/9 -> 0.33333333 | D6: 3
B7: 4 | C7: =B7/9 -> 0.44444444 | D7: 4
B8: 5 | C8: =B8/9 -> 0.55555556 | D8: 6
B9: 6 | C9: =B9/9 -> 0.66666667 | D9: 7
B10: 7 | C10: =B10/9 -> 0.77777778 | D10: 8
B11: 8 | C11: =B11/9 -> 0.88888889 | D11: 9
B12: 9 | C12: =B12/9 -> 1 | D12: 10
B13: 10 | C13: =B13/9 -> 1.1111111 | D13: 11
B14: 11 | C14: =B14/9 -> 1.2222222 | D14: 12
B15: 12 | C15: =B15/9 -> 1.3333333 | D15: 13
... B30: 27 | C30: =B30/9 -> 3 | D30: 30
